reported_result/report-86/ART_ISP_hs/output/output1.txt

Iceberg	1	6	4	9	5	SELL	0	---	0
NewOrderRs	Accepted
	Trades	0
	Orders	1
	Order	Iceberg	1	6	4	9	5	SELL	0	---	3
	Credits	7
	Credit	1	17
	Credit	2	13
	Credit	3	11
	Credit	4	17
	Credit	5	6
	Credit	6	17
	Credit	7	10
	Ownerships	7
	Ownership	1	35
	Ownership	2	66
	Ownership	3	49
	Ownership	4	56
	Ownership	5	42
	Ownership	6	52
	Ownership	7	90
	ReferencePrice	5
	StaticPriceBandLowerLimit	0.6
	StaticPriceBandUpperLimit	0.8
	TotalShares	100
	OwnershipUpperLimit	0.2
	TickSize	1
	LotSize	1
Limit	2	4	5	6	1	BUY 	0	FAK	0
NewOrderRs	Rejected
	Trades	0
	Orders	1
	Order	Iceberg	1	6	4	9	5	SELL	0	---	3
	Credits	7
	Credit	1	17
	Credit	2	13
	Credit	3	11
	Credit	4	17
	Credit	5	6
	Credit	6	17
	Credit	7	10
	Ownerships	7
	Ownership	1	35
	Ownership	2	66
	Ownership	3	49
	Ownership	4	56
	Ownership	5	42
	Ownership	6	52
	Ownership	7	90
	ReferencePrice	5
	StaticPriceBandLowerLimit	0.6
	StaticPriceBandUpperLimit	0.8
	TotalShares	100
	OwnershipUpperLimit	0.2
	TickSize	1
	LotSize	1
Iceberg	3	4	1	2	6	SELL	0	---	0
NewOrderRs	Accepted
	Trades	0
	Orders	2
	Order	Iceberg	3	4	1	2	6	SELL	0	---	6
	Order	Iceberg	1	6	4	9	5	SELL	0	---	3
	Credits	7
	Credit	1	17
	Credit	2	13
	Credit	3	11
	Credit	4	17
	Credit	5	6
	Credit	6	17
	Credit	7	10
	Ownerships	7
	Ownership	1	35
	Ownership	2	66
	Ownership	3	49
	Ownership	4	56
	Ownership	5	42
	Ownership	6	52
	Ownership	7	90
	ReferencePrice	5
	StaticPriceBandLowerLimit	0.6
	StaticPriceBandUpperLimit	0.8
	TotalShares	100
	OwnershipUpperLimit	0.2
	TickSize	1
	LotSize	1
Limit	4	1	4	6	2	BUY 	0	FAK	0
NewOrderRs	Rejected
	Trades	0
	Orders	2
	Order	Iceberg	3	4	1	2	6	SELL	0	---	6
	Order	Iceberg	1	6	4	9	5	SELL	0	---	3
	Credits	7
	Credit	1	17
	Credit	2	13
	Credit	3	11
	Credit	4	17
	Credit	5	6
	Credit	6	17
	Credit	7	10
	Ownerships	7
	Ownership	1	35
	Ownership	2	66
	Ownership	3	49
	Ownership	4	56
	Ownership	5	42
	Ownership	6	52
	Ownership	7	90
	ReferencePrice	5
	StaticPriceBandLowerLimit	0.6
	StaticPriceBandUpperLimit	0.8
	TotalShares	100
	OwnershipUpperLimit	0.2
	TickSize	1
	LotSize	1
CancelOrderRs	Rejected
	Orders	2
	Order	Iceberg	3	4	1	2	6	SELL	0	---	6
	Order	Iceberg	1	6	4	9	5	SELL	0	---	3
	Credits	7
	Credit	1	17
	Credit	2	13
	Credit	3	11
	Credit	4	17
	Credit	5	6
	Credit	6	17
	Credit	7	10
	Ownerships	7
	Ownership	1	35
	Ownership	2	66
	Ownership	3	49
	Ownership	4	56
	Ownership	5	42
	Ownership	6	52
	Ownership	7	90
	ReferencePrice	5
	StaticPriceBandLowerLimit	0.6
	StaticPriceBandUpperLimit	0.8
	TotalShares	100
	OwnershipUpperLimit	0.2
	TickSize	1
	LotSize	1
Limit	6	2	5	8	3	BUY 	0	FAK	0
NewOrderRs	Rejected
	Trades	0
	Orders	2
	Order	Iceberg	3	4	1	2	6	SELL	0	---	6
	Order	Iceberg	1	6	4	9	5	SELL	0	---	3
	Credits	7
	Credit	1	17
	Credit	2	13
	Credit	3	11
	Credit	4	17
	Credit	5	6
	Credit	6	17
	Credit	7	10
	Ownerships	7
	Ownership	1	35
	Ownership	2	66
	Ownership	3	49
	Ownership	4	56
	Ownership	5	42
	Ownership	6	52
	Ownership	7	90
	ReferencePrice	5
	StaticPriceBandLowerLimit	0.6
	StaticPriceBandUpperLimit	0.8
	TotalShares	100
	OwnershipUpperLimit	0.2
	TickSize	1
	LotSize	1
Limit	7	7	3	6	1	BUY 	0	FAK	0
NewOrderRs	Rejected
	Trades	0
	Orders	2
	Order	Iceberg	3	4	1	2	6	SELL	0	---	6
	Order	Iceberg	1	6	4	9	5	SELL	0	---	3
	Credits	7
	Credit	1	17
	Credit	2	13
	Credit	3	11
	Credit	4	17
	Credit	5	6
	Credit	6	17
	Credit	7	10
	Ownerships	7
	Ownership	1	35
	Ownership	2	66
	Ownership	3	49
	Ownership	4	56
	Ownership	5	42
	Ownership	6	52
	Ownership	7	90
	ReferencePrice	5
	StaticPriceBandLowerLimit	0.6
	StaticPriceBandUpperLimit	0.8
	TotalShares	100
	OwnershipUpperLimit	0.2
	TickSize	1
	LotSize	1
Limit	8	5	2	4	2	SELL	0	---	0
NewOrderRs	Accepted
	Trades	0
	Orders	3
	Order	Iceberg	3	4	1	2	6	SELL	0	---	6
	Order	Limit	8	5	2	4	2	SELL	0	---	0
	Order	Iceberg	1	6	4	9	5	SELL	0	---	3
	Credits	7
	Credit	1	17
	Credit	2	13
	Credit	3	11
	Credit	4	17
	Credit	5	6
	Credit	6	17
	Credit	7	10
	Ownerships	7
	Ownership	1	35
	Ownership	2	66
	Ownership	3	49
	Ownership	4	56
	Ownership	5	42
	Ownership	6	52
	Ownership	7	90
	ReferencePrice	5
	StaticPriceBandLowerLimit	0.6
	StaticPriceBandUpperLimit	0.8
	TotalShares	100
	OwnershipUpperLimit	0.2
	TickSize	1
	LotSize	1
Iceberg	9	7	2	9	6	SELL	0	---	0
NewOrderRs	Accepted
	Trades	0
	Orders	4
	Order	Iceberg	3	4	1	2	6	SELL	0	---	6
	Order	Limit	8	5	2	4	2	SELL	0	---	0
	Order	Iceberg	1	6	4	9	5	SELL	0	---	3
	Order	Iceberg	9	7	2	9	6	SELL	0	---	4
	Credits	7
	Credit	1	17
	Credit	2	13
	Credit	3	11
	Credit	4	17
	Credit	5	6
	Credit	6	17
	Credit	7	10
	Ownerships	7
	Ownership	1	35
	Ownership	2	66
	Ownership	3	49
	Ownership	4	56
	Ownership	5	42
	Ownership	6	52
	Ownership	7	90
	ReferencePrice	5
	StaticPriceBandLowerLimit	0.6
	StaticPriceBandUpperLimit	0.8
	TotalShares	100
	OwnershipUpperLimit	0.2
	TickSize	1
	LotSize	1
Limit	10	7	2	5	6	SELL	0	---	0
ReplaceOrderRs	Accepted
	Trades	0
	Orders	4
	Order	Iceberg	3	4	1	2	6	SELL	0	---	6
	Order	Limit	8	5	2	4	2	SELL	0	---	0
	Order	Limit	10	7	2	5	6	SELL	0	---	0
	Order	Iceberg	1	6	4	9	5	SELL	0	---	3
	Credits	7
	Credit	1	17
	Credit	2	13
	Credit	3	11
	Credit	4	17
	Credit	5	6
	Credit	6	17
	Credit	7	10
	Ownerships	7
	Ownership	1	35
	Ownership	2	66
	Ownership	3	49
	Ownership	4	56
	Ownership	5	42
	Ownership	6	52
	Ownership	7	90
	ReferencePrice	5
	StaticPriceBandLowerLimit	0.6
	StaticPriceBandUpperLimit	0.8
	TotalShares	100
	OwnershipUpperLimit	0.2
	TickSize	1
	LotSize	1
