reported_result/report-9/ART_AutoISP/output/output4.txt

Limit	1	4	6	2	8	SELL	8	---	0
NewOrderRs	Eliminated
	Trades	0
	Orders	0
	Credits	7
	Credit	1	19
	Credit	2	13
	Credit	3	20
	Credit	4	9
	Credit	5	16
	Credit	6	1
	Credit	7	20
	Ownerships	7
	Ownership	1	57
	Ownership	2	38
	Ownership	3	56
	Ownership	4	58
	Ownership	5	43
	Ownership	6	49
	Ownership	7	48
	ReferencePrice	5
	StaticPriceBandLowerLimit	0.6
	StaticPriceBandUpperLimit	0.8
	TotalShares	100
	OwnershipUpperLimit	0.2
	TickSize	1
	LotSize	1
Limit	2	2	4	4	5	SELL	0	---	0
NewOrderRs	Accepted
	Trades	0
	Orders	1
	Order	Limit	2	2	4	4	5	SELL	0	---	0
	Credits	7
	Credit	1	19
	Credit	2	13
	Credit	3	20
	Credit	4	9
	Credit	5	16
	Credit	6	1
	Credit	7	20
	Ownerships	7
	Ownership	1	57
	Ownership	2	38
	Ownership	3	56
	Ownership	4	58
	Ownership	5	43
	Ownership	6	49
	Ownership	7	48
	ReferencePrice	5
	StaticPriceBandLowerLimit	0.6
	StaticPriceBandUpperLimit	0.8
	TotalShares	100
	OwnershipUpperLimit	0.2
	TickSize	1
	LotSize	1
Limit	3	7	3	9	8	SELL	0	FAK	0
NewOrderRs	Eliminated
	Trades	0
	Orders	1
	Order	Limit	2	2	4	4	5	SELL	0	---	0
	Credits	7
	Credit	1	19
	Credit	2	13
	Credit	3	20
	Credit	4	9
	Credit	5	16
	Credit	6	1
	Credit	7	20
	Ownerships	7
	Ownership	1	57
	Ownership	2	38
	Ownership	3	56
	Ownership	4	58
	Ownership	5	43
	Ownership	6	49
	Ownership	7	48
	ReferencePrice	5
	StaticPriceBandLowerLimit	0.6
	StaticPriceBandUpperLimit	0.8
	TotalShares	100
	OwnershipUpperLimit	0.2
	TickSize	1
	LotSize	1
Limit	4	5	6	3	4	SELL	0	---	0
NewOrderRs	Accepted
	Trades	0
	Orders	2
	Order	Limit	4	5	6	3	4	SELL	0	---	0
	Order	Limit	2	2	4	4	5	SELL	0	---	0
	Credits	7
	Credit	1	19
	Credit	2	13
	Credit	3	20
	Credit	4	9
	Credit	5	16
	Credit	6	1
	Credit	7	20
	Ownerships	7
	Ownership	1	57
	Ownership	2	38
	Ownership	3	56
	Ownership	4	58
	Ownership	5	43
	Ownership	6	49
	Ownership	7	48
	ReferencePrice	5
	StaticPriceBandLowerLimit	0.6
	StaticPriceBandUpperLimit	0.8
	TotalShares	100
	OwnershipUpperLimit	0.2
	TickSize	1
	LotSize	1
CancelOrderRs	Accepted
	Orders	1
	Order	Limit	2	2	4	4	5	SELL	0	---	0
	Credits	7
	Credit	1	19
	Credit	2	13
	Credit	3	20
	Credit	4	9
	Credit	5	16
	Credit	6	1
	Credit	7	20
	Ownerships	7
	Ownership	1	57
	Ownership	2	38
	Ownership	3	56
	Ownership	4	58
	Ownership	5	43
	Ownership	6	49
	Ownership	7	48
	ReferencePrice	5
	StaticPriceBandLowerLimit	0.6
	StaticPriceBandUpperLimit	0.8
	TotalShares	100
	OwnershipUpperLimit	0.2
	TickSize	1
	LotSize	1
Limit	6	4	2	6	1	BUY 	0	FAK	0
NewOrderRs	Rejected
	Trades	0
	Orders	1
	Order	Limit	2	2	4	4	5	SELL	0	---	0
	Credits	7
	Credit	1	19
	Credit	2	13
	Credit	3	20
	Credit	4	9
	Credit	5	16
	Credit	6	1
	Credit	7	20
	Ownerships	7
	Ownership	1	57
	Ownership	2	38
	Ownership	3	56
	Ownership	4	58
	Ownership	5	43
	Ownership	6	49
	Ownership	7	48
	ReferencePrice	5
	StaticPriceBandLowerLimit	0.6
	StaticPriceBandUpperLimit	0.8
	TotalShares	100
	OwnershipUpperLimit	0.2
	TickSize	1
	LotSize	1
Limit	7	1	2	5	2	SELL	0	---	0
NewOrderRs	Accepted
	Trades	0
	Orders	2
	Order	Limit	2	2	4	4	5	SELL	0	---	0
	Order	Limit	7	1	2	5	2	SELL	0	---	0
	Credits	7
	Credit	1	19
	Credit	2	13
	Credit	3	20
	Credit	4	9
	Credit	5	16
	Credit	6	1
	Credit	7	20
	Ownerships	7
	Ownership	1	57
	Ownership	2	38
	Ownership	3	56
	Ownership	4	58
	Ownership	5	43
	Ownership	6	49
	Ownership	7	48
	ReferencePrice	5
	StaticPriceBandLowerLimit	0.6
	StaticPriceBandUpperLimit	0.8
	TotalShares	100
	OwnershipUpperLimit	0.2
	TickSize	1
	LotSize	1
Iceberg	8	6	5	1	2	BUY 	1	---	0
NewOrderRs	Rejected
	Trades	0
	Orders	2
	Order	Limit	2	2	4	4	5	SELL	0	---	0
	Order	Limit	7	1	2	5	2	SELL	0	---	0
	Credits	7
	Credit	1	19
	Credit	2	13
	Credit	3	20
	Credit	4	9
	Credit	5	16
	Credit	6	1
	Credit	7	20
	Ownerships	7
	Ownership	1	57
	Ownership	2	38
	Ownership	3	56
	Ownership	4	58
	Ownership	5	43
	Ownership	6	49
	Ownership	7	48
	ReferencePrice	5
	StaticPriceBandLowerLimit	0.6
	StaticPriceBandUpperLimit	0.8
	TotalShares	100
	OwnershipUpperLimit	0.2
	TickSize	1
	LotSize	1
Limit	9	7	6	9	4	BUY 	0	---	0
NewOrderRs	Rejected
	Trades	0
	Orders	2
	Order	Limit	2	2	4	4	5	SELL	0	---	0
	Order	Limit	7	1	2	5	2	SELL	0	---	0
	Credits	7
	Credit	1	19
	Credit	2	13
	Credit	3	20
	Credit	4	9
	Credit	5	16
	Credit	6	1
	Credit	7	20
	Ownerships	7
	Ownership	1	57
	Ownership	2	38
	Ownership	3	56
	Ownership	4	58
	Ownership	5	43
	Ownership	6	49
	Ownership	7	48
	ReferencePrice	5
	StaticPriceBandLowerLimit	0.6
	StaticPriceBandUpperLimit	0.8
	TotalShares	100
	OwnershipUpperLimit	0.2
	TickSize	1
	LotSize	1
Limit	10	7	6	9	5	BUY 	0	---	0
ReplaceOrderRs	Rejected
	Trades	0
	Orders	2
	Order	Limit	2	2	4	4	5	SELL	0	---	0
	Order	Limit	7	1	2	5	2	SELL	0	---	0
	Credits	7
	Credit	1	19
	Credit	2	13
	Credit	3	20
	Credit	4	9
	Credit	5	16
	Credit	6	1
	Credit	7	20
	Ownerships	7
	Ownership	1	57
	Ownership	2	38
	Ownership	3	56
	Ownership	4	58
	Ownership	5	43
	Ownership	6	49
	Ownership	7	48
	ReferencePrice	5
	StaticPriceBandLowerLimit	0.6
	StaticPriceBandUpperLimit	0.8
	TotalShares	100
	OwnershipUpperLimit	0.2
	TickSize	1
	LotSize	1
Limit	11	4	6	8	6	SELL	0	---	0
NewOrderRs	Accepted
	Trades	0
	Orders	3
	Order	Limit	2	2	4	4	5	SELL	0	---	0
	Order	Limit	7	1	2	5	2	SELL	0	---	0
	Order	Limit	11	4	6	8	6	SELL	0	---	0
	Credits	7
	Credit	1	19
	Credit	2	13
	Credit	3	20
	Credit	4	9
	Credit	5	16
	Credit	6	1
	Credit	7	20
	Ownerships	7
	Ownership	1	57
	Ownership	2	38
	Ownership	3	56
	Ownership	4	58
	Ownership	5	43
	Ownership	6	49
	Ownership	7	48
	ReferencePrice	5
	StaticPriceBandLowerLimit	0.6
	StaticPriceBandUpperLimit	0.8
	TotalShares	100
	OwnershipUpperLimit	0.2
	TickSize	1
	LotSize	1
Iceberg	12	5	7	7	1	BUY 	0	---	0
NewOrderRs	Rejected
	Trades	0
	Orders	3
	Order	Limit	2	2	4	4	5	SELL	0	---	0
	Order	Limit	7	1	2	5	2	SELL	0	---	0
	Order	Limit	11	4	6	8	6	SELL	0	---	0
	Credits	7
	Credit	1	19
	Credit	2	13
	Credit	3	20
	Credit	4	9
	Credit	5	16
	Credit	6	1
	Credit	7	20
	Ownerships	7
	Ownership	1	57
	Ownership	2	38
	Ownership	3	56
	Ownership	4	58
	Ownership	5	43
	Ownership	6	49
	Ownership	7	48
	ReferencePrice	5
	StaticPriceBandLowerLimit	0.6
	StaticPriceBandUpperLimit	0.8
	TotalShares	100
	OwnershipUpperLimit	0.2
	TickSize	1
	LotSize	1
Limit	13	7	6	8	4	BUY 	0	FAK	0
NewOrderRs	Rejected
	Trades	0
	Orders	3
	Order	Limit	2	2	4	4	5	SELL	0	---	0
	Order	Limit	7	1	2	5	2	SELL	0	---	0
	Order	Limit	11	4	6	8	6	SELL	0	---	0
	Credits	7
	Credit	1	19
	Credit	2	13
	Credit	3	20
	Credit	4	9
	Credit	5	16
	Credit	6	1
	Credit	7	20
	Ownerships	7
	Ownership	1	57
	Ownership	2	38
	Ownership	3	56
	Ownership	4	58
	Ownership	5	43
	Ownership	6	49
	Ownership	7	48
	ReferencePrice	5
	StaticPriceBandLowerLimit	0.6
	StaticPriceBandUpperLimit	0.8
	TotalShares	100
	OwnershipUpperLimit	0.2
	TickSize	1
	LotSize	1
Iceberg	14	2	1	1	6	BUY 	3	---	0
NewOrderRs	Rejected
	Trades	0
	Orders	3
	Order	Limit	2	2	4	4	5	SELL	0	---	0
	Order	Limit	7	1	2	5	2	SELL	0	---	0
	Order	Limit	11	4	6	8	6	SELL	0	---	0
	Credits	7
	Credit	1	19
	Credit	2	13
	Credit	3	20
	Credit	4	9
	Credit	5	16
	Credit	6	1
	Credit	7	20
	Ownerships	7
	Ownership	1	57
	Ownership	2	38
	Ownership	3	56
	Ownership	4	58
	Ownership	5	43
	Ownership	6	49
	Ownership	7	48
	ReferencePrice	5
	StaticPriceBandLowerLimit	0.6
	StaticPriceBandUpperLimit	0.8
	TotalShares	100
	OwnershipUpperLimit	0.2
	TickSize	1
	LotSize	1
CancelOrderRs	Rejected
	Orders	3
	Order	Limit	2	2	4	4	5	SELL	0	---	0
	Order	Limit	7	1	2	5	2	SELL	0	---	0
	Order	Limit	11	4	6	8	6	SELL	0	---	0
	Credits	7
	Credit	1	19
	Credit	2	13
	Credit	3	20
	Credit	4	9
	Credit	5	16
	Credit	6	1
	Credit	7	20
	Ownerships	7
	Ownership	1	57
	Ownership	2	38
	Ownership	3	56
	Ownership	4	58
	Ownership	5	43
	Ownership	6	49
	Ownership	7	48
	ReferencePrice	5
	StaticPriceBandLowerLimit	0.6
	StaticPriceBandUpperLimit	0.8
	TotalShares	100
	OwnershipUpperLimit	0.2
	TickSize	1
	LotSize	1
Iceberg	16	2	3	1	6	SELL	0	---	0
NewOrderRs	Rejected
	Trades	0
	Orders	3
	Order	Limit	2	2	4	4	5	SELL	0	---	0
	Order	Limit	7	1	2	5	2	SELL	0	---	0
	Order	Limit	11	4	6	8	6	SELL	0	---	0
	Credits	7
	Credit	1	19
	Credit	2	13
	Credit	3	20
	Credit	4	9
	Credit	5	16
	Credit	6	1
	Credit	7	20
	Ownerships	7
	Ownership	1	57
	Ownership	2	38
	Ownership	3	56
	Ownership	4	58
	Ownership	5	43
	Ownership	6	49
	Ownership	7	48
