reported_result/report-9/ART_AutoISP/output/output5.txt

Iceberg	1	4	6	4	2	SELL	0	---	0
NewOrderRs	Accepted
	Trades	0
	Orders	1
	Order	Iceberg	1	4	6	4	2	SELL	0	---	2
	Credits	7
	Credit	1	3
	Credit	2	10
	Credit	3	8
	Credit	4	11
	Credit	5	17
	Credit	6	4
	Credit	7	3
	Ownerships	7
	Ownership	1	57
	Ownership	2	82
	Ownership	3	15
	Ownership	4	46
	Ownership	5	75
	Ownership	6	50
	Ownership	7	83
	ReferencePrice	5
	StaticPriceBandLowerLimit	0.6
	StaticPriceBandUpperLimit	0.8
	TotalShares	100
	OwnershipUpperLimit	0.2
	TickSize	1
	LotSize	2
Limit	2	1	4	6	8	BUY 	0	FAK	0
NewOrderRs	Rejected
	Trades	0
	Orders	1
	Order	Iceberg	1	4	6	4	2	SELL	0	---	2
	Credits	7
	Credit	1	3
	Credit	2	10
	Credit	3	8
	Credit	4	11
	Credit	5	17
	Credit	6	4
	Credit	7	3
	Ownerships	7
	Ownership	1	57
	Ownership	2	82
	Ownership	3	15
	Ownership	4	46
	Ownership	5	75
	Ownership	6	50
	Ownership	7	83
	ReferencePrice	5
	StaticPriceBandLowerLimit	0.6
	StaticPriceBandUpperLimit	0.8
	TotalShares	100
	OwnershipUpperLimit	0.2
	TickSize	1
	LotSize	2
Limit	3	5	2	3	8	BUY 	0	---	0
NewOrderRs	Rejected
	Trades	0
	Orders	1
	Order	Iceberg	1	4	6	4	2	SELL	0	---	2
	Credits	7
	Credit	1	3
	Credit	2	10
	Credit	3	8
	Credit	4	11
	Credit	5	17
	Credit	6	4
	Credit	7	3
	Ownerships	7
	Ownership	1	57
	Ownership	2	82
	Ownership	3	15
	Ownership	4	46
	Ownership	5	75
	Ownership	6	50
	Ownership	7	83
	ReferencePrice	5
	StaticPriceBandLowerLimit	0.6
	StaticPriceBandUpperLimit	0.8
	TotalShares	100
	OwnershipUpperLimit	0.2
	TickSize	1
	LotSize	2
Limit	4	7	6	4	1	SELL	0	---	0
NewOrderRs	Rejected
	Trades	0
	Orders	1
	Order	Iceberg	1	4	6	4	2	SELL	0	---	2
	Credits	7
	Credit	1	3
	Credit	2	10
	Credit	3	8
	Credit	4	11
	Credit	5	17
	Credit	6	4
	Credit	7	3
	Ownerships	7
	Ownership	1	57
	Ownership	2	82
	Ownership	3	15
	Ownership	4	46
	Ownership	5	75
	Ownership	6	50
	Ownership	7	83
	ReferencePrice	5
	StaticPriceBandLowerLimit	0.6
	StaticPriceBandUpperLimit	0.8
	TotalShares	100
	OwnershipUpperLimit	0.2
	TickSize	1
	LotSize	2
CancelOrderRs	Rejected
	Orders	1
	Order	Iceberg	1	4	6	4	2	SELL	0	---	2
	Credits	7
	Credit	1	3
	Credit	2	10
	Credit	3	8
	Credit	4	11
	Credit	5	17
	Credit	6	4
	Credit	7	3
	Ownerships	7
	Ownership	1	57
	Ownership	2	82
	Ownership	3	15
	Ownership	4	46
	Ownership	5	75
	Ownership	6	50
	Ownership	7	83
	ReferencePrice	5
	StaticPriceBandLowerLimit	0.6
	StaticPriceBandUpperLimit	0.8
	TotalShares	100
	OwnershipUpperLimit	0.2
	TickSize	1
	LotSize	2
Iceberg	6	7	7	6	4	SELL	0	---	0
NewOrderRs	Accepted
	Trades	0
	Orders	2
	Order	Iceberg	1	4	6	4	2	SELL	0	---	2
	Order	Iceberg	6	7	7	6	4	SELL	0	---	2
	Credits	7
	Credit	1	3
	Credit	2	10
	Credit	3	8
	Credit	4	11
	Credit	5	17
	Credit	6	4
	Credit	7	3
	Ownerships	7
	Ownership	1	57
	Ownership	2	82
	Ownership	3	15
	Ownership	4	46
	Ownership	5	75
	Ownership	6	50
	Ownership	7	83
	ReferencePrice	5
	StaticPriceBandLowerLimit	0.6
	StaticPriceBandUpperLimit	0.8
	TotalShares	100
	OwnershipUpperLimit	0.2
	TickSize	1
	LotSize	2
Iceberg	7	5	1	8	3	SELL	1	---	0
NewOrderRs	Rejected
	Trades	0
	Orders	2
	Order	Iceberg	1	4	6	4	2	SELL	0	---	2
	Order	Iceberg	6	7	7	6	4	SELL	0	---	2
	Credits	7
	Credit	1	3
	Credit	2	10
	Credit	3	8
	Credit	4	11
	Credit	5	17
	Credit	6	4
	Credit	7	3
	Ownerships	7
	Ownership	1	57
	Ownership	2	82
	Ownership	3	15
	Ownership	4	46
	Ownership	5	75
	Ownership	6	50
	Ownership	7	83
	ReferencePrice	5
	StaticPriceBandLowerLimit	0.6
	StaticPriceBandUpperLimit	0.8
	TotalShares	100
	OwnershipUpperLimit	0.2
	TickSize	1
	LotSize	2
Limit	8	1	7	2	8	SELL	0	---	0
NewOrderRs	Accepted
	Trades	0
	Orders	3
	Order	Limit	8	1	7	2	8	SELL	0	---	0
	Order	Iceberg	1	4	6	4	2	SELL	0	---	2
	Order	Iceberg	6	7	7	6	4	SELL	0	---	2
	Credits	7
	Credit	1	3
	Credit	2	10
	Credit	3	8
	Credit	4	11
	Credit	5	17
	Credit	6	4
	Credit	7	3
	Ownerships	7
	Ownership	1	57
	Ownership	2	82
	Ownership	3	15
	Ownership	4	46
	Ownership	5	75
	Ownership	6	50
	Ownership	7	83
	ReferencePrice	5
	StaticPriceBandLowerLimit	0.6
	StaticPriceBandUpperLimit	0.8
	TotalShares	100
	OwnershipUpperLimit	0.2
	TickSize	1
	LotSize	2
Limit	9	3	4	4	7	SELL	0	FAK	0
NewOrderRs	Rejected
	Trades	0
	Orders	3
	Order	Limit	8	1	7	2	8	SELL	0	---	0
	Order	Iceberg	1	4	6	4	2	SELL	0	---	2
	Order	Iceberg	6	7	7	6	4	SELL	0	---	2
	Credits	7
	Credit	1	3
	Credit	2	10
	Credit	3	8
	Credit	4	11
	Credit	5	17
	Credit	6	4
	Credit	7	3
	Ownerships	7
	Ownership	1	57
	Ownership	2	82
	Ownership	3	15
	Ownership	4	46
	Ownership	5	75
	Ownership	6	50
	Ownership	7	83
	ReferencePrice	5
	StaticPriceBandLowerLimit	0.6
	StaticPriceBandUpperLimit	0.8
	TotalShares	100
	OwnershipUpperLimit	0.2
	TickSize	1
	LotSize	2
Limit	10	3	4	2	7	SELL	0	FAK	0
ReplaceOrderRs	Rejected
	Trades	0
	Orders	3
	Order	Limit	8	1	7	2	8	SELL	0	---	0
	Order	Iceberg	1	4	6	4	2	SELL	0	---	2
	Order	Iceberg	6	7	7	6	4	SELL	0	---	2
	Credits	7
	Credit	1	3
	Credit	2	10
	Credit	3	8
	Credit	4	11
	Credit	5	17
	Credit	6	4
	Credit	7	3
	Ownerships	7
	Ownership	1	57
	Ownership	2	82
	Ownership	3	15
	Ownership	4	46
	Ownership	5	75
	Ownership	6	50
	Ownership	7	83
	ReferencePrice	5
	StaticPriceBandLowerLimit	0.6
	StaticPriceBandUpperLimit	0.8
	TotalShares	100
	OwnershipUpperLimit	0.2
	TickSize	1
	LotSize	2
Limit	11	6	6	3	8	SELL	0	---	0
NewOrderRs	Accepted
	Trades	0
	Orders	4
	Order	Limit	8	1	7	2	8	SELL	0	---	0
	Order	Limit	11	6	6	3	8	SELL	0	---	0
	Order	Iceberg	1	4	6	4	2	SELL	0	---	2
	Order	Iceberg	6	7	7	6	4	SELL	0	---	2
	Credits	7
	Credit	1	3
	Credit	2	10
	Credit	3	8
	Credit	4	11
	Credit	5	17
	Credit	6	4
	Credit	7	3
	Ownerships	7
	Ownership	1	57
	Ownership	2	82
	Ownership	3	15
	Ownership	4	46
	Ownership	5	75
	Ownership	6	50
	Ownership	7	83
	ReferencePrice	5
	StaticPriceBandLowerLimit	0.6
	StaticPriceBandUpperLimit	0.8
	TotalShares	100
	OwnershipUpperLimit	0.2
	TickSize	1
	LotSize	2
Limit	12	5	1	5	8	BUY 	0	---	0
NewOrderRs	Rejected
	Trades	0
	Orders	4
	Order	Limit	8	1	7	2	8	SELL	0	---	0
	Order	Limit	11	6	6	3	8	SELL	0	---	0
	Order	Iceberg	1	4	6	4	2	SELL	0	---	2
	Order	Iceberg	6	7	7	6	4	SELL	0	---	2
	Credits	7
	Credit	1	3
	Credit	2	10
	Credit	3	8
	Credit	4	11
	Credit	5	17
	Credit	6	4
	Credit	7	3
	Ownerships	7
	Ownership	1	57
	Ownership	2	82
	Ownership	3	15
	Ownership	4	46
	Ownership	5	75
	Ownership	6	50
	Ownership	7	83
	ReferencePrice	5
	StaticPriceBandLowerLimit	0.6
	StaticPriceBandUpperLimit	0.8
	TotalShares	100
	OwnershipUpperLimit	0.2
	TickSize	1
	LotSize	2
Iceberg	13	1	5	6	8	SELL	0	---	0
NewOrderRs	Accepted
	Trades	0
	Orders	5
	Order	Limit	8	1	7	2	8	SELL	0	---	0
	Order	Limit	11	6	6	3	8	SELL	0	---	0
	Order	Iceberg	1	4	6	4	2	SELL	0	---	2
	Order	Iceberg	6	7	7	6	4	SELL	0	---	2
	Order	Iceberg	13	1	5	6	8	SELL	0	---	3
	Credits	7
	Credit	1	3
	Credit	2	10
	Credit	3	8
	Credit	4	11
	Credit	5	17
	Credit	6	4
	Credit	7	3
	Ownerships	7
	Ownership	1	57
	Ownership	2	82
	Ownership	3	15
	Ownership	4	46
	Ownership	5	75
	Ownership	6	50
	Ownership	7	83
	ReferencePrice	5
	StaticPriceBandLowerLimit	0.6
	StaticPriceBandUpperLimit	0.8
	TotalShares	100
	OwnershipUpperLimit	0.2
	TickSize	1
	LotSize	2
Limit	14	4	2	10	4	SELL	2	---	0
NewOrderRs	Rejected
	Trades	0
	Orders	5
	Order	Limit	8	1	7	2	8	SELL	0	---	0
	Order	Limit	11	6	6	3	8	SELL	0	---	0
	Order	Iceberg	1	4	6	4	2	SELL	0	---	2
	Order	Iceberg	6	7	7	6	4	SELL	0	---	2
	Order	Iceberg	13	1	5	6	8	SELL	0	---	3
	Credits	7
	Credit	1	3
	Credit	2	10
	Credit	3	8
	Credit	4	11
	Credit	5	17
	Credit	6	4
	Credit	7	3
	Ownerships	7
	Ownership	1	57
	Ownership	2	82
	Ownership	3	15
	Ownership	4	46
	Ownership	5	75
	Ownership	6	50
	Ownership	7	83
	ReferencePrice	5
	StaticPriceBandLowerLimit	0.6
	StaticPriceBandUpperLimit	0.8
	TotalShares	100
	OwnershipUpperLimit	0.2
	TickSize	1
	LotSize	2
CancelOrderRs	Rejected
	Orders	5
	Order	Limit	8	1	7	2	8	SELL	0	---	0
	Order	Limit	11	6	6	3	8	SELL	0	---	0
	Order	Iceberg	1	4	6	4	2	SELL	0	---	2
	Order	Iceberg	6	7	7	6	4	SELL	0	---	2
	Order	Iceberg	13	1	5	6	8	SELL	0	---	3
	Credits	7
	Credit	1	3
	Credit	2	10
	Credit	3	8
	Credit	4	11
	Credit	5	17
	Credit	6	4
	Credit	7	3
	Ownerships	7
	Ownership	1	57
	Ownership	2	82
	Ownership	3	15
	Ownership	4	46
	Ownership	5	75
	Ownership	6	50
	Ownership	7	83
	ReferencePrice	5
	StaticPriceBandLowerLimit	0.6
	StaticPriceBandUpperLimit	0.8
	TotalShares	100
